Workbook

Sheet 01 — START HERE
B2: WEDDING PLANNER
B3: Semua persiapan pernikahanmu, lebih terarah.
B5: 💍 PANDUAN MEMULAI PERSIAPAN PERNIKAHAN
B6: Nama Pasangan | C6: Rina & Arif | F6: Tanggal Pernikahan | G6: 12 Oktober 2026
B7: Lokasi Akad & Resepsi | C7: Grand Harmony Hotel, Jakarta Selatan | F7: Target Tamu / Kursi | G7: 250 Undangan (500 Tamu / Pax)
B8: Alokasi Total Budget | C8: 120000000 | F8: Konsep Acara | G8: Romantic Warm Floral & Intimate Elegance
B10: 📋 7 LANGKAH MUDAH PENGGUNAAN TEMPLATE
B11: NO | C11: LANGKAH UTAMA | D11: SHEET TUJUAN | E11: PANDUAN & CARA MENGISI
B12: 1 | C12: Mulai dari Budget | D12: 03 — BUDGET | E12: Tentukan batas kemampuan dan alokasikan estimasi dana untuk venue, catering, dekorasi, hingga dana darurat.
B13: 2 | C13: Cicil Checklist | D13: 04 — CHECKLIST | E13: Cek tugas berdasarkan fase waktu (12-9 bulan s/d Hari H). Update status saat tugas selesai.
B14: 3 | C14: Catat & Kunci Vendor | D14: 06 — VENDOR | E14: Simpan nomor kontak, tanggal pelunasan, DP yang sudah dibayar, serta rincian kontrak kerja sama.
B15: 4 | C15: Susun Daftar Tamu | D15: 07 — GUEST LIST | E15: Kelompokkan tamu dari CPW/CPP, jenis undangan (cetak/digital), jumlah kursi, dan pantau status RSVP.
B16: 5 | C16: Atur Seserahan | D16: 08 — SESERAHAN | E16: Catat barang seserahan berdasarkan 8 kategori rapi, lengkap dengan brand impian dan anggarannya.
B17: 6 | C17: Lengkapi Administrasi | D17: 09 — ADMINISTRASI | E17: Ikuti checklist berkas KUA/Catatan Sipil dan pahami 6 tahapan alur pendaftaran secara terstruktur.
B18: 7 | C18: Pantau di Dashboard | D18: 02 — DASHBOARD | E18: Lihat gambaran besar persiapan, sisa budget, progress checklist, dan grafik interaktif secara otomatis.
B20: 💡 TIPS PENTING WEDDING PLANNING (SIMPLE & REAL)
B21: 1. Kunci Tanggal & Venue Terlebih Dahulu: Venue dan tanggal cantik di Indonesia seringkali di-booking 9-12 bulan sebelumnya.
B22: 2. Alokasikan Dana Cadangan Minimal 5%: Pengeluaran mendadak selalu terjadi (tambahan porsi keluarga, seragam dadakan, tips kru).
B23: 3. Jangan Bayar Pelunasan Sebelum H-14: Simpan termin pelunasan mendekati Hari H setelah seluruh pesanan diverifikasi tuntas.
B24: 4. Komunikasi Terbuka dengan Kedua Keluarga: Sepakati sejak awal porsi undangan dan pembagian tanggung jawab agar tetap harmonis.

Sheet 02 — DASHBOARD
B2: WEDDING COMMAND CENTER
B3: Pantau seluruh kemajuan persiapan, status anggaran, dan RSVP tamu secara real-time.
B5: 💍 RINA & ARIF • 12 OKTOBER 2026 | G5: 📍 Grand Harmony Hotel, Jakarta Selatan • COUNTDOWN: H-20 HARI
B7: TOTAL ANGGARAN | D7: TOTAL REALISASI | F7: SISA ANGGARAN | H7: PROGRESS CHECKLIST | J7: ESTIMASI KURSI HADIR
B8: ='03 — BUDGET'!B6 | D8: ='03 — BUDGET'!F6 | F8: ='03 — BUDGET'!J6 | H8: ='04 — CHECKLIST'!I6 | J8: ='07 — GUEST LIST'!I6
B11: ⚡ NEXT THINGS TO DO (ACTION ITEMS PRIORITAS TINGGI)
B12: NO | C12: PRIORITAS | D12: TUGAS & KEGIATAN KRUSIAL | G12: DEADLINE | H12: STATUS | I12: PANDUAN EKSEKUSI
B13: 1 | C13: Tinggi | D13: Finalisasi rekap data tamu & konfirmasi kursi katering | G13: 28 Sep 2026 | H13: Dalam Proses | I13: Perbarui angka RSVP di sheet 07 — GUEST LIST agar katering akurat
B14: 2 | C14: Tinggi | D14: Technical Meeting (TM) seluruh vendor dan kru WO di venue | G14: 12 Sep 2026 | H14: Dalam Proses | I14: Penyelarasan layout dekorasi, panggung, dan audio sound gedung
B15: 3 | C15: Tinggi | D15: Pelunasan termin pembayaran vendor utama sebelum H-14 | G15: 01 Okt 2026 | H15: Belum Mulai | I15: Pantau sisa tagihan pada sheet 06 — VENDOR
B16: 4 | C16: Tinggi | D16: Pengambilan seluruh kotak seserahan hias & mahar frame | G16: 03 Okt 2026 | H16: Belum Mulai | I16: Cek kelengkapan barang pada sheet 08 — SESERAHAN
B17: 5 | C17: Tinggi | D17: Verifikasi berkas fisik dan kehadiran di KUA bersama wali | G17: 28 Sep 2026 | H17: Dalam Proses | I17: Pastikan seluruh syarat pada sheet 09 — ADMINISTRASI lengkap
B18: 6 | C18: Sedang | D18: Gladi resik akad nikah & pembacaan ijab qobul khidmat | G18: 07 Okt 2026 | H18: Belum Mulai | I18: Simulasi bersama calon pengantin, wali nikah, dan saksi
M20: STATUS RSVP | N20: JUMLAH
M21: Konfirmasi Hadir | N21: ='07 — GUEST LIST'!F6
M22: Belum Konfirmasi | N22: ='07 — GUEST LIST'!G6
M23: Tidak Hadir | N23: ='07 — GUEST LIST'!H6
M26: STATUS CHECKLIST | N26: JUMLAH
M27: Selesai | N27: ='04 — CHECKLIST'!D6
M28: Dalam Proses | N28: ='04 — CHECKLIST'!F6
M29: Belum Mulai | N29: ='04 — CHECKLIST'!H6

Sheet 03 — BUDGET
B2: BUDGET PERNIKAHAN
B3: Rincian alokasi dana, estimasi vendor, pembayaran DP, dan realisasi pengeluaran.
B5: TOTAL ANGGARAN | D5: TOTAL ESTIMASI | F5: TOTAL REALISASI | H5: TOTAL DP DIBAYAR | J5: SISA BUDGET (ANGGARAN - REALISASI)
B6: =SUM(G11:G41) | D6: =SUM(H11:H41) | F6: =SUM(I11:I41) | H6: =SUM(J11:J41) | J6: =B6-F6
B10: NO | C10: KATEGORI | D10: ITEM KEBUTUHAN | E10: REKOMENDASI VENDOR | F10: QTY / SATUAN | G10: ANGGARAN | H10: ESTIMASI | I10: REALISASI | J10: DP DIBAYAR | K10: SISA BUDGET | L10: STATUS | M10: CATATAN / DETAIL | O10: KATEGORI | P10: ANGGARAN | Q10: REALISASI
B11: 1 | C11: Venue & Gedung | D11: Sewa Grand Harmony Ballroom | E11: Grand Harmony Hotel | F11: 1 Paket (6 Jam) | G11: 18000000 | H11: 17500000 | I11: 17500000 | J11: 10000000 | K11: =G11-I11 | L11: Booked | M11: Include AC, panggung, listrik 10.000 watt, 2 ruang rias | O11: Venue & Gedung | P11: =SUMIF($C$11:$C$41, "Venue & Gedung", $G$11:$G$41) | Q11: =SUMIF($C$11:$C$41, "Venue & Gedung", $I$11:$I$41)
B12: 2 | C12: Venue & Gedung | D12: Biaya Kebersihan & Keamanan Gedung | E12: Pengelola Gedung | F12: 1 Kali | G12: 1500000 | H12: 1500000 | I12: 1500000 | J12: 1500000 | K12: =G12-I12 | L12: Lunas | M12: Wajib disetor H-14 | O12: Catering | P12: =SUMIF($C$11:$C$41, "Catering", $G$11:$G$41) | Q12: =SUMIF($C$11:$C$41, "Catering", $I$11:$I$41)
B13: 3 | C13: Catering | D13: Buffet Utama Nusantara (500 pax) | E13: Sari Rasa Catering | F13: 500 Pax | G13: 32500000 | H13: 31000000 | I13: 31000000 | J13: 15000000 | K13: =G13-I13 | L13: Booked | M13: Menu 6 lauk utama + sop + nasi + puding + buah segar | O13: Dekorasi | P13: =SUMIF($C$11:$C$41, "Dekorasi", $G$11:$G$41) | Q13: =SUMIF($C$11:$C$41, "Dekorasi", $I$11:$I$41)
B14: 4 | C14: Catering | D14: Food Stall: Sate Ayam & Siomay | E14: Sari Rasa Catering | F14: 300 Porsi | G14: 5500000 | H14: 5200000 | I14: 5200000 | J14: 2500000 | K14: =G14-I14 | L14: Booked | M14: 200 porsi sate + 100 porsi siomay Bandung | O14: MUA & Busana | P14: =SUMIF($C$11:$C$41, "MUA & Busana", $G$11:$G$41) | Q14: =SUMIF($C$11:$C$41, "MUA & Busana", $I$11:$I$41)
B15: 5 | C15: Catering | D15: Food Stall: Zuppa Soup & Kambing Guling | E15: Sari Rasa Catering | F15: 200 Porsi | G15: 6000000 | H15: 5800000 | I15: 5800000 | J15: 3000000 | K15: =G15-I15 | L15: Booked | M15: Favorit tamu undangan | O15: Dokumentasi | P15: =SUMIF($C$11:$C$41, "Dokumentasi", $G$11:$G$41) | Q15: =SUMIF($C$11:$C$41, "Dokumentasi", $I$11:$I$41)
B16: 6 | C16: Catering | D16: Dessert Bar & Ice Cream Corner | E16: Gelato Bliss | F16: 250 Cup | G16: 2500000 | H16: 2200000 | I16: 2200000 | J16: 1000000 | K16: =G16-I16 | L16: Booked | M16: 5 varian rasa gelato premium | O16: Undangan & Souvenir | P16: =SUMIF($C$11:$C$41, "Undangan & Souvenir", $G$11:$G$41) | Q16: =SUMIF($C$11:$C$41, "Undangan & Souvenir", $I$11:$I$41)
B17: 7 | C17: Dekorasi | D17: Pelaminan Modern Floral (8 Meter) | E17: Bloom & Co. Atelier | F17: 1 Paket | G17: 9000000 | H17: 8500000 | I17: 8500000 | J17: 5000000 | K17: =G17-I17 | L17: Booked | M17: Kombinasi fresh flowers & artificial premium | O17: Entertainment | P17: =SUMIF($C$11:$C$41, "Entertainment", $G$11:$G$41) | Q17: =SUMIF($C$11:$C$41, "Entertainment", $I$11:$I$41)
B18: 8 | C18: Dekorasi | D18: Dekorasi Lorong Masuk & Photo Booth | E18: Bloom & Co. Atelier | F18: 1 Paket | G18: 3500000 | H18: 3000000 | I18: 3000000 | J18: 1500000 | K18: =G18-I18 | L18: Booked | M18: Spot photo gallery 6 frame estetik | O18: Wedding Organizer | P18: =SUMIF($C$11:$C$41, "Wedding Organizer", $G$11:$G$41) | Q18: =SUMIF($C$11:$C$41, "Wedding Organizer", $I$11:$I$41)
B19: 9 | C19: Dekorasi | D19: Lighting Ambience & Karpet Jalan | E19: Bloom & Co. Atelier | F19: 1 Set | G19: 2000000 | H19: 1800000 | I19: 1800000 | J19: 1000000 | K19: =G19-I19 | L19: Booked | M19: Warm white ambiance + spotlight pelaminan | O19: Seserahan & Mahar | P19: =SUMIF($C$11:$C$41, "Seserahan & Mahar", $G$11:$G$41) | Q19: =SUMIF($C$11:$C$41, "Seserahan & Mahar", $I$11:$I$41)
B20: 10 | C20: MUA & Busana | D20: Paket Rias Pengantin Akad & Resepsi | E20: Nadia Beauty MUA | F20: 1 Pasang | G20: 4000000 | H20: 3800000 | I20: 3800000 | J20: 2000000 | K20: =G20-I20 | L20: Booked | M20: Include hijab do/hair do & touch up sampai acara usai | O20: Transport & Hotel | P20: =SUMIF($C$11:$C$41, "Transport & Hotel", $G$11:$G$41) | Q20: =SUMIF($C$11:$C$41, "Transport & Hotel", $I$11:$I$41)
B21: 11 | C21: MUA & Busana | D21: Sewa Kebaya & Beskap Pengantin | E21: Sanggar Rias Ayu | F21: 2 Pasang | G21: 3500000 | H21: 3200000 | I21: 3200000 | J21: 2000000 | K21: =G21-I21 | L21: Booked | M21: Kebaya putih akad + gaun resepsi terracotta rose | O21: Administrasi | P21: =SUMIF($C$11:$C$41, "Administrasi", $G$11:$G$41) | Q21: =SUMIF($C$11:$C$41, "Administrasi", $I$11:$I$41)
B22: 12 | C22: MUA & Busana | D22: Rias & Busana Orang Tua (4 Orang) | E22: Sanggar Rias Ayu | F22: 4 Orang | G22: 2500000 | H22: 2400000 | I22: 2400000 | J22: 1200000 | K22: =G22-I22 | L22: Booked | M22: Seragam kebaya ibu & beskap bapak | O22: Honeymoon & Cadangan | P22: =SUMIF($C$11:$C$41, "Honeymoon & Cadangan", $G$11:$G$41) | Q22: =SUMIF($C$11:$C$41, "Honeymoon & Cadangan", $I$11:$I$41)
B23: 13 | C23: MUA & Busana | D23: Rias & Seragam Bridesmaid & Pagar Ayu | E23: Nadia Beauty Team | F23: 6 Orang | G23: 2000000 | H23: 1800000 | I23: 1800000 | J23: 1000000 | K23: =G23-I23 | L23: Booked | M23: Make up natural fresh look
B24: 14 | C24: Dokumentasi | D24: Foto & Cinematic Video (Akad + Resepsi) | E24: Lensa Kita Photography | F24: 1 Paket | G24: 5500000 | H24: 5000000 | I24: 5000000 | J24: 2500000 | K24: =G24-I24 | L24: Booked | M24: 2 Fotografer, 1 Videografer, teaser 1 menit + full video
B25: 15 | C25: Dokumentasi | D25: Album Kolase Exclusive + Wooden Box USB | E25: Lensa Kita Photography | F25: 2 Album | G25: 1500000 | H25: 1300000 | I25: 1300000 | J25: 1300000 | K25: =G25-I25 | L25: Lunas | M25: Ukuran 20x30 magnetic box
B26: 16 | C26: Dokumentasi | D26: Sesi Foto Prewedding Outdoor | E26: Lensa Kita Photography | F26: 1 Sesi | G26: 2500000 | H26: 2200000 | I26: 2200000 | J26: 2200000 | K26: =G26-I26 | L26: Lunas | M26: Lokasi Kebun Raya Bogor (include izin)
B27: 17 | C27: Undangan & Souvenir | D27: Cetak Undangan Fisik Hardcover Premium | E27: Cerita Kita Undangan | F27: 100 Pcs | G27: 1800000 | H27: 1600000 | I27: 1600000 | J27: 1000000 | K27: =G27-I27 | L27: Booked | M27: Foil emas timbul + amplop kalkir
B28: 18 | C28: Undangan & Souvenir | D28: Website Undangan Digital & RSVP WhatsApp | E28: KiteInvites Studio | F28: 1 Paket | G28: 450000 | H28: 400000 | I28: 400000 | J28: 400000 | K28: =G28-I28 | L28: Lunas | M28: Domain custom rinaarif.com aktif 1 tahun
B29: 19 | C29: Undangan & Souvenir | D29: Souvenir Custom Cutlery Set & Pouch Belacu | E29: Manis Kenangan Souvenir | F29: 300 Pcs | G29: 3500000 | H29: 3200000 | I29: 3200000 | J29: 2000000 | K29: =G29-I29 | L29: Booked | M29: Include kemasan box kraft & thank you card
B30: 20 | C30: Entertainment | D30: Akustik Band 4 Player + Singer | E30: Nada Harmoni Acoustic | F30: 1 Paket (3 Jam) | G30: 2500000 | H30: 2200000 | I30: 2200000 | J30: 1000000 | K30: =G30-I30 | L30: Booked | M30: Lagu pop romantis & jazz santai
B31: 21 | C31: Entertainment | D31: Professional Master of Ceremony (MC) | E31: Mas Dimas MC | F31: Akad & Resepsi | G31: 2000000 | H31: 1800000 | I31: 1800000 | J31: 1000000 | K31: =G31-I31 | L31: Booked | M31: Bilingual MC bahasa Indonesia & santun
B32: 22 | C32: Entertainment | D32: Sound System 5.000 Watt + Genset | E32: Thunder Audio Gedung | F32: 1 Paket | G32: 2200000 | H32: 2000000 | I32: 2000000 | J32: 1000000 | K32: =G32-I32 | L32: Booked | M32: Microphone wireless 4 unit
B33: 23 | C33: Wedding Organizer | D33: WO Hari H (6 Orang Onsite Crew) | E33: Amanah Wedding Organizer | F33: 1 Tim | G33: 4500000 | H33: 4000000 | I33: 4000000 | J33: 2000000 | K33: =G33-I33 | L33: Booked | M33: Mengatur rundown, VIP guest, prasmanan, & timeline
B34: 24 | C34: Seserahan & Mahar | D34: Jasa Hias Kotak Akrilik Hantaran | E34: Kotak Cinta Seserahan | F34: 8 Kotak | G34: 1200000 | H34: 1000000 | I34: 1000000 | J34: 500000 | K34: =G34-I34 | L34: Booked | M34: Sewa box akrilik + hias bunga artificial
... B41: 31 | C41: Honeymoon & Cadangan | D41: Paket Honeymoon Bali Intimate (4D3N) | E41: Nusantara Tour | F41: 1 Paket | G41: 4500000 | H41: 4200000 | I41: 4200000 | J41: 2000000 | K41: =G41-I41 | L41: Booked | M41: Tiket PP + Private Pool Villa Ubud
B42: TOTAL KESELURUHAN PENGELUARAN | G42: =SUM(G11:G41) | H42: =SUM(H11:H41) | I42: =SUM(I11:I41) | J42: =SUM(J11:J41) | K42: =SUM(K11:K41) | L42: Dalam Proses | M42: Untuk tips kru, parkir, dan konsumsi panitia

Sheet 04 — CHECKLIST
B2: CHECKLIST PERSIAPAN PERNIKAHAN
B3: Pantau seluruh tugas persiapan pernikahanmu dari H-12 Bulan hingga Hari Bahagia.
B5: TOTAL TUGAS | D5: TUGAS SELESAI | F5: DALAM PROSES | H5: BELUM MULAI | I5: PROGRESS KELENGKAPAN
B6: =COUNTA(D11:D55) | D6: =COUNTIF(I11:I55, "Selesai") | F6: =COUNTIF(I11:I55, "Dalam Proses") | H6: =COUNTIF(I11:I55, "Belum Mulai") | I6: =D6/B6
B10: ✓ | C10: NO | D10: TASK / KEGIATAN | E10: FASE WAKTU | F10: KATEGORI | G10: PRIORITAS | H10: TARGET DEADLINE | I10: STATUS | J10: CATATAN & PIC
B11: ✓ | C11: 1 | D11: Diskusi awal keluarga besar dan penentuan tanggal pernikahan | E11: 12–9 Bulan | F11: Umum | G11: Tinggi | H11: 12 Nov 2025 | I11: Selesai | J11: Tanggal disepakati 12 Oktober 2026
B12: ✓ | C12: 2 | D12: Menentukan total anggaran maksimal & komitmen pembagian budget | E12: 12–9 Bulan | F12: Budget | G12: Tinggi | H12: 20 Nov 2025 | I12: Selesai | J12: Alokasi budget Rp120 Juta
B13: ✓ | C13: 3 | D13: Menentukan konsep pernikahan (Tradisional Modern / Intimate) | E13: 12–9 Bulan | F13: Konsep | G13: Sedang | H13: 01 Des 2025 | I13: Selesai | J13: Tema romantic plum floral
B14: ✓ | C14: 4 | D14: Survey dan booking venue akad & resepsi (Grand Harmony) | E14: 12–9 Bulan | F14: Venue | G14: Tinggi | H14: 15 Des 2025 | I14: Selesai | J14: DP ballroom telah disetor
B15: ✓ | C15: 5 | D15: Menyusun estimasi kasar jumlah tamu undangan kedua belah pihak | E15: 12–9 Bulan | F15: Tamu | G15: Tinggi | H15: 05 Jan 2026 | I15: Selesai | J15: Target 250 undangan / 500 pax
B16: ✓ | C16: 6 | D16: Survey dan pemilihan vendor catering (Test food menu utama) | E16: 8–6 Bulan | F16: Catering | G16: Tinggi | H16: 15 Feb 2026 | I16: Selesai | J16: Sari Rasa Catering dipilih
B17: ✓ | C17: 7 | D17: Survey dan booking vendor dekorasi pelaminan & photobooth | E17: 8–6 Bulan | F17: Dekorasi | G17: Tinggi | H17: 28 Feb 2026 | I17: Selesai | J17: Bloom & Co. Atelier
B18: ✓ | C18: 8 | D18: Booking MUA pengantin, keluarga, dan busana pernikahan | E18: 8–6 Bulan | F18: MUA & Busana | G18: Tinggi | H18: 15 Mar 2026 | I18: Selesai | J18: Nadia Beauty & Sanggar Ayu
B19: ✓ | C19: 9 | D19: Booking tim dokumentasi foto & cinematic video | E19: 8–6 Bulan | F19: Dokumentasi | G19: Tinggi | H19: 30 Mar 2026 | I19: Selesai | J19: Lensa Kita Photography
B20: ✓ | C20: 10 | D20: Sesi foto pre-wedding outdoor & pemilihan foto terbaik | E20: 8–6 Bulan | F20: Dokumentasi | G20: Sedang | H20: 15 Apr 2026 | I20: Selesai | J20: Foto di Kebun Raya Bogor sukses
B21: ✓ | C21: 11 | D21: Menentukan pengiring pengantin (Bridesmaid & Groomsmen) | E21: 8–6 Bulan | F21: Panitia | G21: Rendah | H21: 30 Apr 2026 | I21: Selesai | J21: 6 sahabat dekat CPW & CPP
B22: ✓ | C22: 12 | D22: Desain & cetak sampel undangan fisik hardcover | E22: 5–3 Bulan | F22: Undangan | G22: Sedang | H22: 15 Mei 2026 | I22: Selesai | J22: Sample foil disetujui
... B57: ⬜ | C57: 47 | D57: Pelaksanaan Resepsi Pernikahan penuh bahagia (Jam 11.00 WIB) | E57: Hari H | F57: Acara | G57: Tinggi | H57: 12 Okt 2026 | I57: Belum Mulai | J57: Menyambut keluarga dan sahabat

Sheet 05 — TIMELINE
B2: TIMELINE & ROADMAP PERNIKAHAN
B3: Pemetaan tonggak pencapaian (milestone) dan jadwal persiapan terpadu.
B5: FASE 1 • H-12 s/d H-9 Bulan | E5: FASE 2 • H-8 s/d H-6 Bulan | H5: FASE 3 • H-5 s/d H-3 Bulan
B6: Fondasi & Anggaran | E6: Core Vendors | H6: Desain & Busana
B7: Penentuan tanggal, komitmen budget, booking venue akad & ballroom. | E7: Test food catering, booking dekorasi, MUA, dokumentasi, foto prewed. | H7: Cetak undangan, booking WO, fitting busana, cicil seserahan & cincin.
B9: FASE 4 • H-2 s/d H-1 Bulan | E9: FASE 5 • H-14 s/d H-1 | H9: FASE 6 • HARI H
B10: Administrasi & Tamu | E10: Final Countdown | H10: The Big Day
B11: Berkas KUA SIMKAH, sebar undangan, packing seserahan, rundown. | E11: Pelunasan vendor, TM vendor, gladi resik, check-in hotel persiapan. | H11: Akad nikah khidmat, resepsi bahagia, dokumentasi kenangan abadi.
B13: 📅 JADWAL MASTER PERSIAPAN & PENANGGUNG JAWAB (PIC)
B14: NO | C14: TAHAPAN WAKTU | D14: AGENDA & TARGET EKSEKUSI | F14: DEADLINE | G14: PIC UTAMA | H14: STATUS | I14: CATATAN KOORDINASI
B15: 1 | C15: H-12 Bulan | D15: Pertemuan kedua keluarga, penentuan tanggal, alokasi budget | F15: 15 Nov 2025 | G15: Kedua Calon & Ortu | H15: Selesai | I15: Disepakati tanggal 12 Okt 2026
B16: 2 | C16: H-11 Bulan | D16: Survey venue ballroom Jakarta Selatan & ketersediaan tanggal | F16: 15 Des 2025 | G16: Arif & Rina | H16: Selesai | I16: Grand Harmony Ballroom di-booking
B17: 3 | C17: H-9 Bulan | D17: Test food catering keluarga & survey paket rekanan | F17: 15 Feb 2026 | G17: Ibu Rina & Arif | H17: Selesai | I17: Sari Rasa 500 pax dipilih
B18: 4 | C18: H-8 Bulan | D18: Booking dekorasi pelaminan modern floral & dokumentasi foto | F18: 15 Mar 2026 | G18: Rina | H18: Selesai | I18: Bloom & Co. & Lensa Kita
B19: 5 | C19: H-7 Bulan | D19: Booking MUA pengantin, busana akad, dan seragam keluarga | F19: 15 Apr 2026 | G19: Rina & Ibu | H19: Selesai | I19: Nadia Beauty & Sanggar Ayu
B20: 6 | C20: H-6 Bulan | D20: Sesi foto prewedding di Kebun Raya Bogor | F20: 15 Mei 2026 | G20: Arif & Rina | H20: Selesai | I20: Teaser prewed siap
B21: 7 | C21: H-5 Bulan | D21: Finalisasi desain undangan fisik, digital, dan souvenir | F21: 15 Jun 2026 | G21: Arif | H21: Selesai | I21: Undangan dicetak 100 pcs
B22: 8 | C22: H-4 Bulan | D22: Booking Wedding Organizer (WO) & cicil belanja seserahan | F22: 15 Jul 2026 | G22: Arif & Rina | H22: Selesai | I22: Amanah WO siap berkolaborasi
B23: 9 | C23: H-3 Bulan | D23: Fitting pertama busana pengantin & beli cincin kawin | F23: 15 Agu 2026 | G23: Rina & Arif | H23: Selesai | I23: Spilla Jewelry rose gold
B24: 10 | C24: H-2 Bulan | D24: Pengurusan surat RT/RW, Kelurahan N1-N4 & Puskesmas | F24: 10 Sep 2026 | G24: Arif & Ayah Rina | H24: Dalam Proses | I24: Surat rekomendasi nikah diurus
B25: 11 | C25: H-1 Bulan | D25: Distribusi undangan fisik & broadcast website undangan | F25: 20 Sep 2026 | G25: Keluarga Besar | H25: Dalam Proses | I25: Distribusi berjalan 70%
B26: 12 | C26: H-30 | D26: Technical Meeting seluruh vendor & tim WO di venue | F26: 12 Sep 2026 | G26: WO & Tim Vendor | H26: Dalam Proses | I26: Rundown v2 diselaraskan
... B30: 16 | C30: Hari H | D30: Akad Nikah Khidmat (08.00) & Resepsi Pernikahan (11.00) | F30: 12 Okt 2026 | G30: Seluruh Pihak | H30: Belum Mulai | I30: Puncak hari bahagia

Sheet 06 — VENDOR
B2: VENDOR DIRECTORY & PAYMENT TRACKER
B3: Daftar kontak vendor rekanan, nilai kontrak, termin DP, dan jadwal pelunasan.
B5: TOTAL KONTRAK VENDOR | D5: TOTAL DP TERBAYAR | F5: SISA TAGIHAN PELUNASAN | H5: VENDOR SUDAH LUNAS | J5: PROGRESS PELUNASAN
B6: =SUM(G11:G26) | D6: =SUM(H11:H26) | F6: =SUM(I11:I26) | H6: =COUNTIF(K11:K26, "Lunas") | J6: =D6/B6
B10: NO | C10: NAMA VENDOR | D10: KATEGORI | E10: KONTAK / PIC | F10: INSTAGRAM | G10: NILAI KONTRAK | H10: DP DIBAYAR | I10: SISA PELUNASAN | J10: DEADLINE PELUNASAN | K10: STATUS BAYAR | L10: CATATAN / BENEFIT
B11: 1 | C11: Grand Harmony Ballroom | D11: Venue | E11: Pak Gunawan (0812-3456-7890) | F11: @grandharmony_ballroom | G11: 17500000 | H11: 10000000 | I11: =G11-H11 | J11: 28 Sep 2026 | K11: Booked | L11: Include AC central, soundsystem gedung, 2 ruang rias VIP
B12: 2 | C12: Sari Rasa Catering | D12: Catering | E12: Ibu Dewi (0813-8888-1234) | F12: @sarirasa_catering | G12: 44200000 | H12: 21500000 | I12: =G12-H12 | J12: 28 Sep 2026 | K12: Booked | L12: Paket buffet 500 pax + 3 food stall favorit + bonus 50 porsi
B13: 3 | C13: Bloom & Co. Atelier | D13: Dekorasi | E13: Mba Clara (0811-9988-7766) | F13: @bloomandco_wedding | G13: 13300000 | H13: 7500000 | I13: =G13-H13 | J13: 28 Sep 2026 | K13: Booked | L13: Pelaminan 8 meter fresh flowers, photobooth, karpet rose petal
B14: 4 | C14: Nadia Beauty MUA | D14: MUA | E14: Nadia Safira (0856-7788-9900) | F14: @nadiabeauty_mua | G14: 5600000 | H14: 3000000 | I14: =G14-H14 | J14: 01 Okt 2026 | K14: Booked | L14: Rias pengantin akad & resepsi + retouch + rias ibu & pagar ayu
B15: 5 | C15: Sanggar Rias Ayu | D15: Busana | E15: Ibu Ayu (0815-4433-2211) | F15: @sanggarayu_kebaya | G15: 5600000 | H15: 3200000 | I15: =G15-H15 | J15: 01 Okt 2026 | K15: Booked | L15: 2 pasang baju pengantin + beskap bapak & kebaya ibu 4 stel
B16: 6 | C16: Lensa Kita Photography | D16: Dokumentasi | E16: Mas Fajar (0817-6655-4433) | F16: @lensakita_photo | G16: 8500000 | H16: 6000000 | I16: =G16-H16 | J16: 01 Okt 2026 | K16: Booked | L16: 2 Foto, 1 Video cinematic, teaser 1 min, album kolase 20x30
B17: 7 | C17: Cerita Kita Undangan | D17: Undangan | E17: Admin (0821-3344-5566) | F17: @ceritakita_invitation | G17: 1600000 | H17: 1000000 | I17: =G17-H17 | J17: 25 Sep 2026 | K17: Booked | L17: Cetak undangan fisik 100 pcs foil emas + kartu ucapan terima kasih
B18: 8 | C18: KiteInvites Studio | D18: Undangan Digital | E18: Mas Bayu (0852-1122-3344) | F18: @kiteinvites | G18: 400000 | H18: 400000 | I18: =G18-H18 | J18: 15 Mei 2026 | K18: Lunas | L18: Website rinaarif.com + musik latar + RSVP WhatsApp otomatis
B19: 9 | C19: Manis Kenangan Souvenir | D19: Souvenir | E19: Ibu Maya (0878-9900-1122) | F19: @maniskenangan_souvenir | G19: 3200000 | H19: 2000000 | I19: =G19-H19 | J19: 25 Sep 2026 | K19: Booked | L19: 300 cutlery set pouch belacu estetik + sablon inisial
B20: 10 | C20: Nada Harmoni Acoustic | D20: Entertainment | E20: Mas Rangga (0819-2233-4455) | F20: @nadaharmoni_band | G20: 2200000 | H20: 1000000 | I20: =G20-H20 | J20: 05 Okt 2026 | K20: Booked | L20: Akustik 4 personil + singer profesional
B21: 11 | C21: Mas Dimas MC | D21: MC | E21: Dimas Setiawan (0812-7766-5544) | F21: @masdimas_mc | G21: 1800000 | H21: 1000000 | I21: =G21-H21 | J21: 05 Okt 2026 | K21: Booked | L21: MC akad & resepsi komunikatif & berpengalaman
B22: 12 | C22: Thunder Audio Gedung | D22: Sound System | E22: Pak Slamet (0813-2211-0099) | F22: @thunder_audiosystem | G22: 2000000 | H22: 1000000 | I22: =G22-H22 | J22: 28 Sep 2026 | K22: Booked | L22: Sound 5000 watt + 4 wireless mic + operator standby
... B26: 16 | C26: Royal Executive Rent | D26: Transport | E26: Pak Harto (0811-3322-1100) | F26: @royalrent_jakarta | G26: 1600000 | H26: 1000000 | I26: =G26-H26 | J26: 05 Okt 2026 | K26: Booked | L26: Sewa Alphard putih 12 jam include bensin, driver & dekorasi bunga
B27: TOTAL KONTRAK & PEMBAYARAN VENDOR | G27: =SUM(G11:G26) | H27: =SUM(H11:H26) | I27: =SUM(I11:I26)

Sheet 07 — GUEST LIST
B2: DAFTAR TAMU
B3: Kelola daftar undangan, klasifikasi hubungan keluarga/rekan, alokasi kursi, dan RSVP.
B5: TOTAL UNDANGAN | D5: TOTAL KURSI | E5: SUDAH RSVP | F5: KONFIRMASI HADIR | G5: BELUM RSVP | H5: TIDAK HADIR | I5: ESTIMASI KURSI HADIR
B6: =COUNTA(C11:C65) | D6: =SUM(G11:G65) | E6: =COUNTIF(I11:I65, "Hadir") + COUNTIF(I11:I65, "Tidak Hadir") | F6: =COUNTIF(I11:I65, "Hadir") | G6: =COUNTIF(I11:I65, "Belum") | H6: =COUNTIF(I11:I65, "Tidak Hadir") | I6: =SUMIF(I11:I65, "Hadir", G11:G65)
B10: NO | C10: NAMA TAMU | D10: TAMU DARI | E10: HUBUNGAN | F10: JENIS UNDANGAN | G10: JUMLAH KURSI | H10: STATUS UNDANGAN | I10: RSVP | J10: CATATAN / MEJA
B11: 1 | C11: Sasa & Suami | D11: CPW | E11: Teman Kerja | F11: Cetak | G11: 2 | H11: Terkirim | I11: Hadir | J11: Rekan divisi HRD
B12: 2 | C12: Rina | D12: CPP | E12: Teman Sekolah | F12: Digital | G12: 3 | H12: Belum | I12: Belum | J12: Sahabat SMA Arif
B13: 3 | C13: Budi | D13: CPP | E13: Teman Kerja | F13: Cetak | G13: 1 | H13: Terkirim | I13: Hadir | J13: Senior Programmer
B14: 4 | C14: Andi dan keluarga | D14: CPP | E14: Keluarga | F14: Digital | G14: 3 | H14: Terkirim | I14: Hadir | J14: Sepupu dari Ibu CPP
B15: 5 | C15: Sarah | D15: CPP | E15: Teman Sekolah | F15: Cetak | G15: 2 | H15: Terkirim | I15: Hadir | J15: Alumni SMP
B16: 6 | C16: Dika | D16: CPP | E16: Teman Sekolah | F16: Digital | G16: 1 | H16: Belum | I16: Belum | J16: Sahabat futsal
B17: 7 | C17: Fajar | D17: CPP | E17: Teman Sekolah | F17: Digital | G17: 1 | H17: Belum | I17: Belum | J17: Teman satu band
B18: 8 | C18: Tante Ani | D18: CPW | E18: Keluarga | F18: Digital | G18: 2 | H18: Terkirim | I18: Hadir | J18: Tante kandung CPW
B19: 9 | C19: Bu Sari | D19: CPW | E19: Teman Kerja | F19: Cetak | G19: 1 | H19: Belum | I19: Belum | J19: Manager Keuangan
B20: 10 | C20: Pak Hendra | D20: CPW | E20: Teman Kerja | F20: Digital | G20: 2 | H20: Belum | I20: Belum | J20: Direktur operasional
B21: 11 | C21: Raka | D21: CPP | E21: Teman Kerja | F21: Cetak | G21: 3 | H21: Terkirim | I21: Hadir | J21: Rekan satu divisi
B22: 12 | C22: Kak Dini | D22: CPP | E22: Teman Sekolah | F22: Cetak | G22: 1 | H22: Terkirim | I22: Hadir | J22: Senior kampus
... B65: 55 | C65: dr. Hendro & Istri | D65: CPW | E65: Keluarga | F65: Cetak | G65: 2 | H65: Terkirim | I65: Hadir | J65: Dokter keluarga / Om

Sheet 08 — SESERAHAN
B2: LIST SESERAHAN
B3: Perencanaan dan realisasi 8 kotak seserahan pernikahan impian.
B5: BUDGET SESERAHAN | D5: REALISASI SESERAHAN | F5: SISA BUDGET SESERAHAN | H5: TOTAL BARANG | I5: STATUS SELESAI
B6: =F56 | D6: =G56 | F6: =B6-D6 | H6: =COUNTA(D11:D58) | I6: =COUNTIF(H11:H58, "Done")/B6
B10: NO | C10: KATEGORI | D10: BARANG | E10: BRAND | F10: ANGGARAN | G10: REALISASI | H10: STATUS | I10: CATATAN / TOKO | L10: KATEGORI SESERAHAN | M10: REALISASI
B11: 1 | C11: 1. Perlengkapan Ibadah | D11: Al-Qur'an Tajwid Terjemahan A5 | E11: Cordoba Premium | F11: 300000 | G11: 280000 | H11: Done | I11: Cover emboss rose gold | L11: 1. Perlengkapan Ibadah | M11: =G15
D12: Mukena Silk Sutra Bordir | E12: Tazkia Hijab | F12: 650000 | G12: 600000 | H12: Done | I12: Bahan lembut include sajadah muka | L12: 2. Pakaian & Hijab | M12: =G21
D13: Sajadah Tenun Turki Premium | E13: Lokal Brand | F13: 250000 | G13: 250000 | H13: Done | I13: Warna beige motif kubah | L13: 3. Skincare Routine | M13: =G27
D14: Tasbih Mutiara Kristal | E14: Lokal Handmade | F14: 150000 | G14: 120000 | H14: Done | I14: 33 butir kristal cantik | L14: 4. Bodycare & Haircare | M14: =G34
B15: TOTAL 1. PERLENGKAPAN IBADAH | F15: =SUM(F11:F14) | G15: =SUM(G11:G14) | L15: 5. Makeup & Kosmetik | M15: =G42
B16: 2 | C16: 2. Pakaian & Hijab | D16: Dress Pesta Silk Satin | E16: Zara | F16: 850000 | G16: 799000 | H16: Done | I16: Warna dusty rose ukuran M | L16: 6. Tas, Sepatu & Aksesoris | M16: =G47
D17: Setelan Gamis Modest | E17: Hijup | F17: 700000 | G17: 650000 | H17: Done | I17: Bahan flowy elegan | L17: 7. Elektronik & Styling Tools | M17: =G51
D18: Hijab Voal Ultrafine | E18: Buttonscarves | F18: 425000 | G18: 425000 | H18: Done | I18: Motif Monogram Series | L18: 8. Paket Bedding & Perlengkapan Kamar | M18: =G55
D19: Pashmina Silk Ceruty | E19: Elzatta | F19: 175000 | G19: 150000 | H19: Done | I19: Warna champagne nude
D20: Set Baju Tidur Piyama Satin | E20: Sorex | F20: 250000 | G20: 220000 | H20: Done | I20: Model kimono tidur
B21: TOTAL 2. PAKAIAN & HIJAB | F21: =SUM(F16:F20) | G21: =SUM(G16:G20)
B22: 3 | C22: 3. Skincare Routine | D22: Facial Wash Low pH Cleanser | E22: Skintific | F22: 120000 | G22: 99000 | H22: Done | I22: Gentle cleanser ceramide
D23: Hydrating & Soothing Toner | E23: Skintific | F23: 160000 | G23: 135000 | H23: Done | I23: Centella soothing toner
D24: Moisturizer Gel 5X Ceramide | E24: The Originote | F24: 90000 | G24: 75000 | H24: Done | I24: Lock moisture 24 jam
D25: Sunscreen SPF 50+ PA++++ | E25: Azarine | F25: 110000 | G25: 89000 | H25: Done | I25: Hydrasoothe sun gel
D26: Brightening Glow Serum | E26: Avoskin | F26: 170000 | G26: 145000 | H26: Done | I26: Miraculous refining serum
B27: TOTAL 3. SKINCARE ROUTINE | F27: =SUM(F22:F26) | G27: =SUM(G22:G26)
B28: 4 | C28: 4. Bodycare & Haircare | D28: Body Lotion Gluta-Hya Flawless | E28: Vaseline | F28: 95000 | G28: 80000 | H28: Done | I28: Serum burst UV lotion
D29: Goat Milk Shower Body Wash | E29: The Bath Box | F29: 160000 | G29: 145000 | H29: Done | I29: Aroma almond vanilla
D30: Shampoo Extraordinary Oil | E30: L'Oreal | F30: 140000 | G30: 125000 | H30: Done | I30: Untuk rambut berkilau
D31: Conditioner Total Repair 5 | E31: L'Oreal | F31: 150000 | G31: 135000 | H31: Done | I31: Melembutkan rambut
D32: Hair Creambath Mask Nutritive | E32: Makarizo | F32: 110000 | G32: 95000 | H32: Done | I32: Kandungan royal jelly
D33: Eau De Parfum 100ml | E33: HMNS (Orgasm) | F33: 380000 | G33: 375000 | H33: Done | I33: Aroma vanila mawar mewah
B34: TOTAL 4. BODYCARE & HAIRCARE | F34: =SUM(F28:F33) | G34: =SUM(G28:G33)
B35: 5 | C35: 5. Makeup & Kosmetik | D35: Cushion Copy Paste SPF 35 | E35: Somethinc | F35: 220000 | G35: 189000 | H35: Done | I35: Shade Buttercream medium
D36: Loose Powder Silky Smooth | E36: Make Over | F36: 145000 | G36: 125000 | H36: Done | I36: Matte finish natural
D37: Eyeshadow Palette Goddess | E37: ESQA | F37: 260000 | G37: 230000 | H37: Done | I37: 9 warna shimmer & earthy tone
D38: Blush On Cheek Souffle | E38: Rollover Reaction | F38: 140000 | G38: 120000 | H38: Done | I38: Warna peach blush
D39: Sky High Waterproof Mascara | E39: Maybelline | F39: 150000 | G39: 135000 | H39: Done | I39: Melentikkan tahan 24 jam
D40: Lip Tint Velvet Mousse | E40: Dear Me Beauty | F40: 120000 | G40: 99000 | H40: Done | I40: Warna Dear Amanda
D41: Setting Spray Lock Makeup | E41: Studio Tropik | F41: 130000 | G41: 115000 | H41: Done | I41: DreamSetter glowing spray
B42: TOTAL 5. MAKEUP & KOSMETIK | F42: =SUM(F35:F41) | G42: =SUM(G35:G41)
B43: 6 | C43: 6. Tas, Sepatu & Aksesoris | D43: Quilted Tweed Shoulder Bag | E43: Charles & Keith | F43: 1200000 | G43: 1150000 | H43: Done | I43: Tas selempang elegan
D44: Pointed Toe Flats Shoes | E44: Pedro | F44: 950000 | G44: 899000 | H44: Done | I44: Warna cream size 38
D45: Jam Tangan Petite Rose Gold | E45: Daniel Wellington | F45: 2200000 | G45: 2050000 | H45: Done | I45: Dial putih mesh strap
...

Sheet 09 — ADMINISTRASI
B2: ADMINISTRASI PERSIAPAN PERNIKAHAN
B3: Panduan kelengkapan berkas resmi KUA/Catatan Sipil dan alur birokrasi pendaftaran.
B5: 📑 SYARAT DOKUMEN CALON PENGANTIN (WANITA & PRIA)
B6: NO | C6: SYARAT / DOKUMEN PERSYARATAN | F6: ESTIMASI BIAYA | G6: STATUS BERKAS | H6: CATATAN / KETERANGAN PRAKTIS
B7: 1 | C7: Surat pengantar nikah dari RT / RW setempat (CPW & CPP) | F7: 0 | G7: Selesai | H7: Bawa fotokopi KTP dan KK asli untuk pengantar
B8: 2 | C8: Surat keterangan nikah dari Kelurahan (Model N1 s/d N4) | F8: 0 | G8: Selesai | H8: Diurus di kantor kelurahan domisili
B9: 3 | C9: Fotokopi KTP kedua calon pengantin (masing-masing 4 lembar) | F9: 10000 | G9: Selesai | H9: Fotokopi jelas tidak buram
B10: 4 | C10: Fotokopi Kartu Keluarga (KK) kedua calon pengantin | F10: 5000 | G10: Selesai | H10: Data alamat harus sesuai dengan KTP
B11: 5 | C11: Fotokopi Akta Kelahiran kedua calon pengantin | F11: 5000 | G11: Selesai | H11: Untuk verifikasi nama orang tua
B12: 6 | C12: Fotokopi Ijazah terakhir kedua calon pengantin | F12: 10000 | G12: Selesai | H12: Menyelaraskan ejaan nama di buku nikah
B13: 7 | C13: Pas foto 2x3 (4 lbr) & 4x6 (2 lbr) latar belakang warna biru | F13: 150000 | G13: Selesai | H13: Baju berkerah rapi / jas, cetak doff studio
B14: 8 | C14: Surat keterangan sehat pranikah dari Puskesmas setempat | F14: 200000 | G14: Selesai | H14: Cek lab darah, hemoglobin, dan imunisasi TT wanita
B15: 9 | C15: Persetujuan kedua calon pengantin (Formulir Model N7) | F15: 0 | G15: Selesai | H15: Ditandatangani kedua belah pihak
B16: 10 | C16: Fotokopi KTP orang tua / wali nikah (ayah kandung) | F16: 5000 | G16: Selesai | H16: Jika ayah wafat sertakan surat akta kematian
B17: 11 | C17: Fotokopi KTP 2 orang saksi nikah | F17: 5000 | G17: Selesai | H17: Saksi dari pihak keluarga yang sudah dewasa
B18: 12 | C18: Surat rekomendasi nikah dari KUA asal (Surat Numpang Nikah) | F18: 20000 | G18: Selesai | H18: Khusus jika akad diadakan di kecamatan berbeda
... B26: 20 | C26: Biaya administrasi operasional / transport penghulu KUA | F26: 200000 | G26: Dalam Proses | H26: Disiapkan amplop rapi oleh panitia keluarga
B27: TOTAL BIAYA ADMINISTRASI PERSIAPAN PERNIKAHAN | F27: =SUM(F7:F26)
B30: 🏛️ ALUR PENDAFTARAN PERNIKAHAN RESMI (KUA / CATATAN SIPIL)
B31: Langkah 1 | C31: Datang ke Pengurus RT / RW Setempat | F31: Membawa fotokopi KK dan KTP asli kedua calon untuk mendapatkan Surat Pengantar Nikah resmi dari RT dan RW.
B32: Langkah 2 | C32: Pemeriksaan Kesehatan di Puskesmas | F32: Melakukan skrining kesehatan pranikah, cek golongan darah & hemoglobin, imunisasi TT wanita, serta input aplikasi ELSIMIL.
B33: Langkah 3 | C33: Datang ke Kantor Kelurahan | F33: Menyerahkan surat pengantar RT/RW untuk menerbitkan Formulir N1 (Surat Nikah), N2 (Asal Usul), dan N4 (Surat Orang Tua).
B34: Langkah 4 | C34: Pengurusan Rekomendasi Nikah di KUA Asal | F34: Khusus bagi calon pengantin pria/wanita yang menikah di luar kecamatan asal, wajib meminta Surat Rekomendasi Nikah (Numpang Nikah).
B35: Langkah 5 | C35: Pendaftaran Kehendak Nikah di SIMKAH Online | F35: Input data calon pengantin di situs simkah.kemenag.go.id, upload berkas, dan bayar tagihan PNBP Rp600.000 ke Bank jika menikah di luar kantor KUA.
B36: Langkah 6 | C36: Bimbingan Perkawinan & Verifikasi Akhir | F36: Menghadiri kursus pranikah (Bimwin) dan pemeriksaan berkas fisik di KUA bersama wali nikah minimal H-10 sebelum akad.

Sheet 10 — CATATAN
B2: CATATAN & INSPIRASI PERNIKAHAN
B3: Ruang catatan meeting vendor, ide dekorasi, kontak darurat, dan kesepakatan keluarga.
B5: 📝 CATATAN MEETING VENDOR & KESEPAKATAN
B6: Grand Harmony Hotel | D6: Technical meeting disepakati tanggal 12 September 2026. Ruang rias VIP dapat dipakai mulai jam 04.00 WIB pagi.
B7: Sari Rasa Catering | D7: Menu gubukan zuppa soup ditambah 50 porsi gratis sebagai bonus. Pelayanan es puter dimulai setelah prosesi lempar buket.
B8: Bloom & Co. Dekorasi | D8: Tone warna pelaminan: terracotta rose, plum burgundy, dan aksen gold. Standing floral di aisle menggunakan mawar putih segar.
B9: Lensa Kita Photo | D9: Fotografer standby jam 05.30 WIB untuk liputan prosesi makeup CPW dan detail aksesoris cincin/mahar.
B11: 👥 PANITIA KELUARGA & KONTAK DARURAT HARI H
B12: Penanggung Jawab Acara | D12: Pakde Bambang S. | F12: 0812-9876-5432 | G12: Koordinasi saksi & penghulu KUA
B13: Koordinator Konsumsi | D13: Tante Ani Depok | F13: 0813-1122-3344 | G13: Pengawasan porsi katering & box panitia
B14: Penerima Tamu & Buku Tamu | D14: Sinta & Nanda | F14: 0856-4433-2211 | G14: Standby meja registrasi & souvenir
B15: Bendahara & Angpau | D15: Ibu Rina (Ibu Pengantin) | F15: 0811-2233-4455 | G15: Kunci kotak uang & serah terima amplop tips
B16: Koordinator Logistik & Mobil | D16: Mas Fajar Nugraha | F16: 0818-7766-5544 | G16: Pengawalan seserahan & koper busana
B18: ✨ IDE KREATIF, PLAYLIST & SUASANA ACARA
B19: Lagu Pengiring Masuk Pelaminan | E19: Kisah Romantis - Glenn Fredly / Sampai Jadi Debu - Banda Neira (Versi Akustik)
B20: Konsep Dress Code Undangan | E20: Bebas rapi sopan dengan sentuhan warna pastel / earth tone hangat
B21: Sovenir Tambahan untuk VIP | E21: Kotak teh premium artisan custom label ucapan terima kasih
B22: Moment Penyerahan Mahar | E22: Foto formal bersama kedua orang tua, saksi, dan penghulu langsung setelah ijab qobul
